<?xml version="1.0"?>

<robot name="head_hardware" xmlns:xacro="http://ros.org/wiki/xacro">

  <xacro:property name="PI" value="3.14159"/>
  <xacro:property name="DYNAMIXEL_MESH_SCALE" value="0.001"/>
  
  <xacro:property name="F4_WIDTH" value="0.0480"/>
  <xacro:property name="F4_HEIGHT" value="0.0625"/>
  <xacro:property name="F4_DEPTH" value="0.0245"/>
  
  <xacro:property name="F2_DEPTH" value="0.0245"/>
  <xacro:property name="F2_WIDTH" value="0.0480"/>
  <xacro:property name="F2_HEIGHT" value="0.0380"/>
  
  <xacro:property name="F3_WIDTH" value="0.038"/>
  <xacro:property name="F3_HEIGHT" value="0.009"/>
  <xacro:property name="F3_DEPTH" value="0.025"/>

  <xacro:property name="AX12_HEIGHT" value="0.0385"/>
  <xacro:property name="AX12_WIDTH" value="0.035"/>
  <xacro:property name="AX12_DEPTH" value="0.049"/>

  <xacro:property name="MX28_HEIGHT" value="0.0355"/>
  <xacro:property name="MX28_WIDTH" value="0.0356"/>
  <xacro:property name="MX28_DEPTH" value="0.056"/>



  <xacro:macro name="dynamixel_mx28_fixed" params="parent name *origin">
    <joint name="${name}_joint" type="fixed">
      <xacro:insert_block name="origin" />
      <parent link="${parent}_link"/>
      <child link="${name}_link" />
    </joint>

    <link name="${name}_link">
      <inertial>
        <mass value="0.00001" />
        <origin xyz="0 0 0" />
        <inertia ixx="1.0" ixy="0.0" ixz="0.0" iyy="1.0" iyz="0.0" izz="1.0" />
      </inertial>
      <visual>
        <origin xyz="0 0 0" rpy="0 0 0" />
        <geometry>
          <mesh filename="package://tb2s_description/meshes/dynamixel/mx28.stl" scale="0.001 0.001 0.001"/>
        </geometry>
        <xacro:insert_block name="material_dark_grey" />
      </visual>
      <collision>
        <origin xyz="0 0 0" rpy="0 0 0" />
        <geometry>
          <box size="${MX28_HEIGHT} ${MX28_WIDTH} ${MX28_DEPTH}"/>
        </geometry>
      </collision>
    </link>
  </xacro:macro>




  <xacro:macro name="bioloid_F3_fixed" params="parent name color *origin">
    <joint name="${name}_joint" type="fixed">
      <xacro:insert_block name="origin" />
      <parent link="${parent}_link"/>
      <child link="${name}_link" />
    </joint>

    <link name="${name}_link">
      <inertial>
        <mass value="0.00001" />
        <origin xyz="0 0 0" />
        <inertia ixx="1.0" ixy="0.0" ixz="0.0"
          iyy="1.0" iyz="0.0"
          izz="1.0" />
      </inertial>

      <visual>
        <origin xyz="0 0 0 " rpy="0 0 0" />
        <geometry>
           <mesh filename="package://tb2s_description/meshes/dynamixel/F3.stl" scale="0.001 0.001 0.001"/>
        </geometry>
         <xacro:insert_block name="material_black" />
      </visual>

      <collision>
        <origin xyz="0 0 0" rpy="0 0 0" />
        <geometry>
          <box size="${F3_WIDTH} ${F3_HEIGHT} ${F3_DEPTH}"/>
        </geometry>
      </collision>
    </link>
  </xacro:macro>

  <xacro:macro name="dynamixel_ax12_fixed" params="parent name *origin">
    <joint name="${name}_joint" type="fixed">
      <xacro:insert_block name="origin" />
      <parent link="${parent}_link"/>
      <child link="${name}_link" />
    </joint>

    <link name="${name}_link">
      <inertial>
        <mass value="0.00001" />
        <origin xyz="0 0 0" />
        <inertia ixx="1.0" ixy="0.0" ixz="0.0"
          iyy="1.0" iyz="0.0"
          izz="1.0" />
      </inertial>
      <visual>
        <origin xyz="0 0 0" rpy="0 0 0" />
        <geometry>
          <mesh filename="package://tb2s_description/meshes/dynamixel/ax12.stl" scale="${DYNAMIXEL_MESH_SCALE} ${DYNAMIXEL_MESH_SCALE} ${DYNAMIXEL_MESH_SCALE}"/>
        </geometry>
        <xacro:insert_block name="material_dark_grey" />
      </visual>
      <collision>
        <origin xyz="0 0 -0.01241" rpy="0 0 0" />
        <geometry>
          <box size="${AX12_HEIGHT} ${AX12_WIDTH} ${AX12_DEPTH}"/>
        </geometry>
      </collision>
    </link>
  </xacro:macro>

  <xacro:macro name="bioloid_F3_head_revolute" params="parent name joint_name llimit ulimit vlimit color *origin *axis">
    <joint name="${joint_name}_joint" type="revolute">
      <xacro:insert_block name="origin" />
      <xacro:insert_block name="axis" />
      <parent link="${parent}_link"/>
      <limit lower="${llimit}" upper="${ulimit}" velocity="${vlimit}" effort="1.0" />
      <child link="${name}_link" />
    </joint>

    <link name="${name}_link">
      <inertial>
        <mass value="0.00001" />
        <origin xyz="0 0 0" />
        <inertia ixx="1.0" ixy="0.0" ixz="0.0"
          iyy="1.0" iyz="0.0"
          izz="1.0" />
      </inertial>

      <visual>
        <origin xyz="0 0 0 " rpy="0 0 0" />
        <geometry>
           <mesh filename="package://tb2s_description/meshes/dynamixel/F3.stl" scale="${DYNAMIXEL_MESH_SCALE} ${DYNAMIXEL_MESH_SCALE} ${DYNAMIXEL_MESH_SCALE}"/>
        </geometry>
         <xacro:insert_block name="material_black" />
      </visual>

      <collision>
        <origin xyz="0 0 0" rpy="0 0 0" />
        <geometry>
           <box size="${F3_DEPTH} ${F3_WIDTH} ${F3_HEIGHT}"/>
        </geometry>
      </collision>
    </link>
  </xacro:macro>
  
  <xacro:macro name="bioloid_F2_head_revolute" params="parent name joint_name llimit ulimit vlimit color *origin *axis">
    <joint name="${joint_name}_joint" type="revolute">
      <xacro:insert_block name="origin" />
      <xacro:insert_block name="axis" />
      <parent link="${parent}_link"/>
      <limit lower="${llimit}" upper="${ulimit}" velocity="${vlimit}" effort="1.0" />
      <child link="${name}_link" />
    </joint>

    <link name="${name}_link">
      <inertial>
        <mass value="0.00001" />
        <origin xyz="0 0 0" />
        <inertia ixx="1.0" ixy="0.0" ixz="0.0"
          iyy="1.0" iyz="0.0"
          izz="1.0" />
      </inertial>

      <visual>
        <origin xyz="0 0 0 " rpy="0 0 0" />
        <geometry>
          <mesh filename="package://tb2s_description/meshes/dynamixel/F2.stl" scale="${DYNAMIXEL_MESH_SCALE} ${DYNAMIXEL_MESH_SCALE} ${DYNAMIXEL_MESH_SCALE}"/>
        </geometry>
         <xacro:insert_block name="material_black" />
      </visual>

      <collision>
        <origin xyz="0 0 0" rpy="0 0 0" />
        <geometry>
          <box size="${F2_DEPTH} ${F2_HEIGHT} ${F2_WIDTH}"/>
        </geometry>
      </collision>
    </link>
  </xacro:macro>

</robot>
